[2020-05-04 23:42:52,810] {taskinstance.py:669} INFO - Dependencies all met for <TaskInstance: batch_processing.merge_files 2020-05-04T19:19:03.487724+00:00 [queued]>
[2020-05-04 23:42:52,818] {taskinstance.py:669} INFO - Dependencies all met for <TaskInstance: batch_processing.merge_files 2020-05-04T19:19:03.487724+00:00 [queued]>
[2020-05-04 23:42:52,818] {taskinstance.py:879} INFO - 
--------------------------------------------------------------------------------
[2020-05-04 23:42:52,818] {taskinstance.py:880} INFO - Starting attempt 1 of 2
[2020-05-04 23:42:52,818] {taskinstance.py:881} INFO - 
--------------------------------------------------------------------------------
[2020-05-04 23:42:52,823] {taskinstance.py:900} INFO - Executing <Task(PythonOperator): merge_files> on 2020-05-04T19:19:03.487724+00:00
[2020-05-04 23:42:52,825] {standard_task_runner.py:53} INFO - Started process 22817 to run task
[2020-05-04 23:42:52,861] {logging_mixin.py:112} INFO - Running %s on host %s <TaskInstance: batch_processing.merge_files 2020-05-04T19:19:03.487724+00:00 [running]> eyrunt-mbp
[2020-05-04 23:42:52,871] {taskinstance.py:1145} ERROR - [Errno 2] No such file or directory: '../resources/output0.7567382001217469.csv'
Traceback (most recent call last):
  File "/usr/local/lib/python3.7/site-packages/airflow/models/taskinstance.py", line 983, in _run_raw_task
    result = task_copy.execute(context=context)
  File "/usr/local/lib/python3.7/site-packages/airflow/operators/python_operator.py", line 113, in execute
    return_value = self.execute_callable()
  File "/usr/local/lib/python3.7/site-packages/airflow/operators/python_operator.py", line 118, in execute_callable
    return self.python_callable(*self.op_args, **self.op_kwargs)
  File "/Users/eyrunt/airflow/dags/usage_example.py", line 51, in file_merger
    with open(output_path, 'w') as outfile:
FileNotFoundError: [Errno 2] No such file or directory: '../resources/output0.7567382001217469.csv'
[2020-05-04 23:42:52,876] {taskinstance.py:1168} INFO - Marking task as UP_FOR_RETRY
[2020-05-04 23:43:02,814] {logging_mixin.py:112} INFO - [2020-05-04 23:43:02,812] {local_task_job.py:103} INFO - Task exited with return code 1
