[2020-05-04 23:48:08,521] {taskinstance.py:669} INFO - Dependencies all met for <TaskInstance: batch_processing.merge_files 2020-05-04T19:19:03.487724+00:00 [queued]>
[2020-05-04 23:48:08,531] {taskinstance.py:669} INFO - Dependencies all met for <TaskInstance: batch_processing.merge_files 2020-05-04T19:19:03.487724+00:00 [queued]>
[2020-05-04 23:48:08,531] {taskinstance.py:879} INFO - 
--------------------------------------------------------------------------------
[2020-05-04 23:48:08,531] {taskinstance.py:880} INFO - Starting attempt 2 of 2
[2020-05-04 23:48:08,531] {taskinstance.py:881} INFO - 
--------------------------------------------------------------------------------
[2020-05-04 23:48:08,535] {taskinstance.py:900} INFO - Executing <Task(PythonOperator): merge_files> on 2020-05-04T19:19:03.487724+00:00
[2020-05-04 23:48:08,537] {standard_task_runner.py:53} INFO - Started process 23075 to run task
[2020-05-04 23:48:08,578] {logging_mixin.py:112} INFO - Running %s on host %s <TaskInstance: batch_processing.merge_files 2020-05-04T19:19:03.487724+00:00 [running]> eyrunt-mbp
[2020-05-04 23:48:08,588] {taskinstance.py:1145} ERROR - [Errno 2] No such file or directory: 'Users/eyrunt/Desktop/ftp_imports/output0.3309121380496941.txt'
Traceback (most recent call last):
  File "/usr/local/lib/python3.7/site-packages/airflow/models/taskinstance.py", line 983, in _run_raw_task
    result = task_copy.execute(context=context)
  File "/usr/local/lib/python3.7/site-packages/airflow/operators/python_operator.py", line 113, in execute
    return_value = self.execute_callable()
  File "/usr/local/lib/python3.7/site-packages/airflow/operators/python_operator.py", line 118, in execute_callable
    return self.python_callable(*self.op_args, **self.op_kwargs)
  File "/Users/eyrunt/airflow/dags/usage_example.py", line 51, in file_merger
    with open(output_path, 'w') as outfile:
FileNotFoundError: [Errno 2] No such file or directory: 'Users/eyrunt/Desktop/ftp_imports/output0.3309121380496941.txt'
[2020-05-04 23:48:08,590] {taskinstance.py:1187} INFO - All retries failed; marking task as FAILED.dag_id=batch_processing, task_id=merge_files, execution_date=20200504T191903, start_date=20200504T214808, end_date=20200504T214808
[2020-05-04 23:48:18,520] {logging_mixin.py:112} INFO - [2020-05-04 23:48:18,519] {local_task_job.py:103} INFO - Task exited with return code 1
