[2020-05-04 21:18:26,574] {taskinstance.py:669} INFO - Dependencies all met for <TaskInstance: batch_processing.merge_files 2020-05-03T00:00:00+00:00 [queued]>
[2020-05-04 21:18:26,582] {taskinstance.py:669} INFO - Dependencies all met for <TaskInstance: batch_processing.merge_files 2020-05-03T00:00:00+00:00 [queued]>
[2020-05-04 21:18:26,582] {taskinstance.py:879} INFO - 
--------------------------------------------------------------------------------
[2020-05-04 21:18:26,582] {taskinstance.py:880} INFO - Starting attempt 2 of 2
[2020-05-04 21:18:26,582] {taskinstance.py:881} INFO - 
--------------------------------------------------------------------------------
[2020-05-04 21:18:26,587] {taskinstance.py:900} INFO - Executing <Task(PythonOperator): merge_files> on 2020-05-03T00:00:00+00:00
[2020-05-04 21:18:26,589] {standard_task_runner.py:53} INFO - Started process 12978 to run task
[2020-05-04 21:18:26,629] {logging_mixin.py:112} INFO - Running %s on host %s <TaskInstance: batch_processing.merge_files 2020-05-03T00:00:00+00:00 [running]> eyrunt-mbp
[2020-05-04 21:18:26,640] {taskinstance.py:1145} ERROR - [Errno 2] File b'/Users/eyrunt/Users/eyrunt/Desktop/ftp_imports/fileA.csv' does not exist: b'/Users/eyrunt/Users/eyrunt/Desktop/ftp_imports/fileA.csv'
Traceback (most recent call last):
  File "/usr/local/lib/python3.7/site-packages/airflow/models/taskinstance.py", line 983, in _run_raw_task
    result = task_copy.execute(context=context)
  File "/usr/local/lib/python3.7/site-packages/airflow/operators/python_operator.py", line 113, in execute
    return_value = self.execute_callable()
  File "/usr/local/lib/python3.7/site-packages/airflow/operators/python_operator.py", line 118, in execute_callable
    return self.python_callable(*self.op_args, **self.op_kwargs)
  File "/Users/eyrunt/airflow/dags/usage_example.py", line 59, in file_merger
    a = pd.read_csv("~/Users/eyrunt/Desktop/ftp_imports/fileA.csv")
  File "/usr/local/lib/python3.7/site-packages/pandas/io/parsers.py", line 685, in parser_f
    return _read(filepath_or_buffer, kwds)
  File "/usr/local/lib/python3.7/site-packages/pandas/io/parsers.py", line 457, in _read
    parser = TextFileReader(fp_or_buf, **kwds)
  File "/usr/local/lib/python3.7/site-packages/pandas/io/parsers.py", line 895, in __init__
    self._make_engine(self.engine)
  File "/usr/local/lib/python3.7/site-packages/pandas/io/parsers.py", line 1135, in _make_engine
    self._engine = CParserWrapper(self.f, **self.options)
  File "/usr/local/lib/python3.7/site-packages/pandas/io/parsers.py", line 1917, in __init__
    self._reader = parsers.TextReader(src, **kwds)
  File "pandas/_libs/parsers.pyx", line 382, in pandas._libs.parsers.TextReader.__cinit__
  File "pandas/_libs/parsers.pyx", line 689, in pandas._libs.parsers.TextReader._setup_parser_source
FileNotFoundError: [Errno 2] File b'/Users/eyrunt/Users/eyrunt/Desktop/ftp_imports/fileA.csv' does not exist: b'/Users/eyrunt/Users/eyrunt/Desktop/ftp_imports/fileA.csv'
[2020-05-04 21:18:26,642] {taskinstance.py:1187} INFO - All retries failed; marking task as FAILED.dag_id=batch_processing, task_id=merge_files, execution_date=20200503T000000, start_date=20200504T191826, end_date=20200504T191826
[2020-05-04 21:18:36,575] {logging_mixin.py:112} INFO - [2020-05-04 21:18:36,574] {local_task_job.py:103} INFO - Task exited with return code 1
