[2020-05-04 19:36:15,895] {taskinstance.py:669} INFO - Dependencies all met for <TaskInstance: slack_integration.slack_integration 2020-05-02T00:00:00+00:00 [queued]>
[2020-05-04 19:36:15,904] {taskinstance.py:669} INFO - Dependencies all met for <TaskInstance: slack_integration.slack_integration 2020-05-02T00:00:00+00:00 [queued]>
[2020-05-04 19:36:15,909] {taskinstance.py:879} INFO - 
--------------------------------------------------------------------------------
[2020-05-04 19:36:15,910] {taskinstance.py:880} INFO - Starting attempt 2 of 2
[2020-05-04 19:36:15,910] {taskinstance.py:881} INFO - 
--------------------------------------------------------------------------------
[2020-05-04 19:36:15,915] {taskinstance.py:900} INFO - Executing <Task(SlackWebhookOperator): slack_integration> on 2020-05-02T00:00:00+00:00
[2020-05-04 19:36:15,917] {standard_task_runner.py:53} INFO - Started process 6609 to run task
[2020-05-04 19:36:15,953] {logging_mixin.py:112} INFO - Running %s on host %s <TaskInstance: slack_integration.slack_integration 2020-05-02T00:00:00+00:00 [running]> eyrunt-mbp
[2020-05-04 19:36:15,971] {logging_mixin.py:112} INFO - [2020-05-04 19:36:15,971] {http_hook.py:136} INFO - Sending 'POST' to url: http://T012TB8A8JJ/B0130CTSXFD/bG6KPnbUxhm9z4uyNZj5nx9c
[2020-05-04 19:36:16,114] {logging_mixin.py:112} INFO - [2020-05-04 19:36:16,114] {http_hook.py:185} WARNING - HTTPConnectionPool(host='t012tb8a8jj', port=80): Max retries exceeded with url: /B0130CTSXFD/bG6KPnbUxhm9z4uyNZj5nx9c (Caused by NewConnectionError('<urllib3.connection.HTTPConnection object at 0x10dffa6d0>: Failed to establish a new connection: [Errno 8] nodename nor servname provided, or not known')) Tenacity will retry to execute the operation
[2020-05-04 19:36:16,115] {taskinstance.py:1145} ERROR - HTTPConnectionPool(host='t012tb8a8jj', port=80): Max retries exceeded with url: /B0130CTSXFD/bG6KPnbUxhm9z4uyNZj5nx9c (Caused by NewConnectionError('<urllib3.connection.HTTPConnection object at 0x10dffa6d0>: Failed to establish a new connection: [Errno 8] nodename nor servname provided, or not known'))
Traceback (most recent call last):
  File "/usr/local/lib/python3.7/site-packages/urllib3/connection.py", line 157, in _new_conn
    (self._dns_host, self.port), self.timeout, **extra_kw
  File "/usr/local/lib/python3.7/site-packages/urllib3/util/connection.py", line 61, in create_connection
    for res in socket.getaddrinfo(host, port, family, socket.SOCK_STREAM):
  File "/usr/local/Cellar/python/3.7.6_1/Frameworks/Python.framework/Versions/3.7/lib/python3.7/socket.py", line 752, in getaddrinfo
    for res in _socket.getaddrinfo(host, port, family, type, proto, flags):
socket.gaierror: [Errno 8] nodename nor servname provided, or not known

During handling of the above exception, another exception occurred:

Traceback (most recent call last):
  File "/usr/local/lib/python3.7/site-packages/urllib3/connectionpool.py", line 672, in urlopen
    chunked=chunked,
  File "/usr/local/lib/python3.7/site-packages/urllib3/connectionpool.py", line 387, in _make_request
    conn.request(method, url, **httplib_request_kw)
  File "/usr/local/Cellar/python/3.7.6_1/Frameworks/Python.framework/Versions/3.7/lib/python3.7/http/client.py", line 1252, in request
    self._send_request(method, url, body, headers, encode_chunked)
  File "/usr/local/Cellar/python/3.7.6_1/Frameworks/Python.framework/Versions/3.7/lib/python3.7/http/client.py", line 1298, in _send_request
    self.endheaders(body, encode_chunked=encode_chunked)
  File "/usr/local/Cellar/python/3.7.6_1/Frameworks/Python.framework/Versions/3.7/lib/python3.7/http/client.py", line 1247, in endheaders
    self._send_output(message_body, encode_chunked=encode_chunked)
  File "/usr/local/Cellar/python/3.7.6_1/Frameworks/Python.framework/Versions/3.7/lib/python3.7/http/client.py", line 1026, in _send_output
    self.send(msg)
  File "/usr/local/Cellar/python/3.7.6_1/Frameworks/Python.framework/Versions/3.7/lib/python3.7/http/client.py", line 966, in send
    self.connect()
  File "/usr/local/lib/python3.7/site-packages/urllib3/connection.py", line 184, in connect
    conn = self._new_conn()
  File "/usr/local/lib/python3.7/site-packages/urllib3/connection.py", line 169, in _new_conn
    self, "Failed to establish a new connection: %s" % e
urllib3.exceptions.NewConnectionError: <urllib3.connection.HTTPConnection object at 0x10dffa6d0>: Failed to establish a new connection: [Errno 8] nodename nor servname provided, or not known

During handling of the above exception, another exception occurred:

Traceback (most recent call last):
  File "/usr/local/lib/python3.7/site-packages/requests/adapters.py", line 449, in send
    timeout=timeout
  File "/usr/local/lib/python3.7/site-packages/urllib3/connectionpool.py", line 720, in urlopen
    method, url, error=e, _pool=self, _stacktrace=sys.exc_info()[2]
  File "/usr/local/lib/python3.7/site-packages/urllib3/util/retry.py", line 436, in increment
    raise MaxRetryError(_pool, url, error or ResponseError(cause))
urllib3.exceptions.MaxRetryError: HTTPConnectionPool(host='t012tb8a8jj', port=80): Max retries exceeded with url: /B0130CTSXFD/bG6KPnbUxhm9z4uyNZj5nx9c (Caused by NewConnectionError('<urllib3.connection.HTTPConnection object at 0x10dffa6d0>: Failed to establish a new connection: [Errno 8] nodename nor servname provided, or not known'))

During handling of the above exception, another exception occurred:

Traceback (most recent call last):
  File "/usr/local/lib/python3.7/site-packages/airflow/models/taskinstance.py", line 983, in _run_raw_task
    result = task_copy.execute(context=context)
  File "/usr/local/lib/python3.7/site-packages/airflow/contrib/operators/slack_webhook_operator.py", line 113, in execute
    self.hook.execute()
  File "/usr/local/lib/python3.7/site-packages/airflow/contrib/hooks/slack_webhook_hook.py", line 152, in execute
    extra_options={'proxies': proxies})
  File "/usr/local/lib/python3.7/site-packages/airflow/hooks/http_hook.py", line 137, in run
    return self.run_and_check(session, prepped_request, extra_options)
  File "/usr/local/lib/python3.7/site-packages/airflow/hooks/http_hook.py", line 186, in run_and_check
    raise ex
  File "/usr/local/lib/python3.7/site-packages/airflow/hooks/http_hook.py", line 178, in run_and_check
    allow_redirects=extra_options.get("allow_redirects", True))
  File "/usr/local/lib/python3.7/site-packages/requests/sessions.py", line 646, in send
    r = adapter.send(request, **kwargs)
  File "/usr/local/lib/python3.7/site-packages/requests/adapters.py", line 516, in send
    raise ConnectionError(e, request=request)
requests.exceptions.ConnectionError: HTTPConnectionPool(host='t012tb8a8jj', port=80): Max retries exceeded with url: /B0130CTSXFD/bG6KPnbUxhm9z4uyNZj5nx9c (Caused by NewConnectionError('<urllib3.connection.HTTPConnection object at 0x10dffa6d0>: Failed to establish a new connection: [Errno 8] nodename nor servname provided, or not known'))
[2020-05-04 19:36:16,126] {taskinstance.py:1187} INFO - All retries failed; marking task as FAILED.dag_id=slack_integration, task_id=slack_integration, execution_date=20200502T000000, start_date=20200504T173615, end_date=20200504T173616
[2020-05-04 19:36:25,897] {logging_mixin.py:112} INFO - [2020-05-04 19:36:25,896] {local_task_job.py:103} INFO - Task exited with return code 1
